<sdf version='1.7'>
  <world name='default'>
    <light name='sun' type='directional'>
      <cast_shadows>1</cast_shadows>
      <pose>0 0 10 0 -0 0</pose>
      <diffuse>0.8 0.8 0.8 1</diffuse>
      <specular>0.2 0.2 0.2 1</specular>
      <attenuation>
        <range>1000</range>
        <constant>0.9</constant>
        <linear>0.01</linear>
        <quadratic>0.001</quadratic>
      </attenuation>
      <direction>-0.5 0.1 -0.9</direction>
      <spot>
        <inner_angle>0</inner_angle>
        <outer_angle>0</outer_angle>
        <falloff>0</falloff>
      </spot>
    </light>
    <model name='ground_plane'>
      <static>1</static>
      <link name='link'>
        <collision name='collision'>
          <geometry>
            <plane>
              <normal>0 0 1</normal>
              <size>100 100</size>
            </plane>
          </geometry>
          <surface>
            <contact>
              <collide_bitmask>65535</collide_bitmask>
              <ode/>
            </contact>
            <friction>
              <ode>
                <mu>100</mu>
                <mu2>50</mu2>
              </ode>
              <torsional>
                <ode/>
              </torsional>
            </friction>
            <bounce/>
          </surface>
          <max_contacts>10</max_contacts>
        </collision>
        <visual name='visual'>
          <cast_shadows>0</cast_shadows>
          <geometry>
            <plane>
              <normal>0 0 1</normal>
              <size>100 100</size>
            </plane>
          </geometry>
          <material>
            <script>
              <uri>file://media/materials/scripts/gazebo.material</uri>
              <name>Gazebo/Grey</name>
            </script>
          </material>
        </visual>
        <self_collide>0</self_collide>
        <enable_wind>0</enable_wind>
        <kinematic>0</kinematic>
      </link>
    </model>
    <gravity>0 0 -9.8</gravity>
    <magnetic_field>6e-06 2.3e-05 -4.2e-05</magnetic_field>
    <atmosphere type='adiabatic'/>
    <physics type='ode'>
      <max_step_size>0.001</max_step_size>
      <real_time_factor>1</real_time_factor>
      <real_time_update_rate>1000</real_time_update_rate>
    </physics>
    <scene>
      <ambient>0.4 0.4 0.4 1</ambient>
      <background>0.7 0.7 0.7 1</background>
      <shadows>1</shadows>
    </scene>
    <audio>
      <device>default</device>
    </audio>
    <wind/>
    <spherical_coordinates>
      <surface_model>EARTH_WGS84</surface_model>
      <latitude_deg>0</latitude_deg>
      <longitude_deg>0</longitude_deg>
      <elevation>0</elevation>
      <heading_deg>0</heading_deg>
    </spherical_coordinates>
    <model name='my_bot'>
      <link name='root_link'>
        <inertial>
          <pose>0.000595 0 0.034583 0 -0 0</pose>
          <mass>0.252</mass>
          <inertia>
            <ixx>0.000677235</ixx>
            <ixy>0</ixy>
            <ixz>-1.24375e-05</ixz>
            <iyy>0.000688396</iyy>
            <iyz>0</iyz>
            <izz>0.000442486</izz>
          </inertia>
        </inertial>
        <collision name='root_link_fixed_joint_lump__base_link_collision'>
          <pose>0 0 0.042 0 -0 0</pose>
          <geometry>
            <cylinder>
              <length>0.064</length>
              <radius>0.08</radius>
            </cylinder>
          </geometry>
          <max_contacts>10</max_contacts>
          <surface>
            <contact>
              <ode/>
            </contact>
            <bounce/>
            <friction>
              <torsional>
                <ode/>
              </torsional>
              <ode/>
            </friction>
          </surface>
        </collision>
        <collision name='root_link_fixed_joint_lump__arm_link_1_collision_1'>
          <pose>0.075 0 0.11722 0 -0 0</pose>
          <geometry>
            <box>
              <size>0.008 0.008 0.06</size>
            </box>
          </geometry>
          <max_contacts>10</max_contacts>
          <surface>
            <contact>
              <ode/>
            </contact>
            <bounce/>
            <friction>
              <torsional>
                <ode/>
              </torsional>
              <ode/>
            </friction>
          </surface>
        </collision>
        <collision name='root_link_fixed_joint_lump__arm_link_2_collision_2'>
          <pose>0.075 0 0.1675 0 -0 0</pose>
          <geometry>
            <box>
              <size>0.008 0.008 0.05</size>
            </box>
          </geometry>
          <max_contacts>10</max_contacts>
          <surface>
            <contact>
              <ode/>
            </contact>
            <bounce/>
            <friction>
              <torsional>
                <ode/>
              </torsional>
              <ode/>
            </friction>
          </surface>
        </collision>
        <collision name='root_link_fixed_joint_lump__laser_frame_collision_3'>
          <pose>0 0 0.0848 0 -0 0</pose>
          <geometry>
            <cylinder>
              <length>0.02</length>
              <radius>0.02</radius>
            </cylinder>
          </geometry>
          <surface>
            <contact>
              <ode/>
            </contact>
            <friction>
              <ode/>
              <torsional>
                <ode/>
              </torsional>
            </friction>
            <bounce/>
          </surface>
          <max_contacts>10</max_contacts>
        </collision>
        <visual name='root_link_fixed_joint_lump__base_link_visual'>
          <pose>0 0 0 0 -0 0</pose>
          <geometry>
            <mesh>
              <scale>1 1 1</scale>
              <uri>file:///home/deepanshu/My_ROS/src/r_bot/description/meshes/hb_crystal.dae</uri>
            </mesh>
          </geometry>
        </visual>
        <visual name='root_link_fixed_joint_lump__arm_link_1_visual_1'>
          <pose>0.075 0 0.0925 0 -0 0</pose>
          <geometry>
            <mesh>
              <scale>1 1 1</scale>
              <uri>file:///home/deepanshu/My_ROS/src/r_bot/description/meshes/arm_link.dae</uri>
            </mesh>
          </geometry>
        </visual>
        <visual name='root_link_fixed_joint_lump__arm_link_2_visual_2'>
          <pose>0.075 0 0.1425 0 -0 0</pose>
          <geometry>
            <mesh>
              <scale>1 1 1</scale>
              <uri>file:///home/deepanshu/My_ROS/src/r_bot/description/meshes/arm_elbow.dae</uri>
            </mesh>
          </geometry>
        </visual>
        <visual name='root_link_fixed_joint_lump__laser_frame_visual_3'>
          <pose>0 0 0.0848 0 -0 0</pose>
          <geometry>
            <cylinder>
              <length>0.02</length>
              <radius>0.02</radius>
            </cylinder>
          </geometry>
          <material>
            <script>
              <name>Gazebo/Red</name>
              <uri>file://media/materials/scripts/gazebo.material</uri>
            </script>
          </material>
        </visual>
        <sensor name='laser' type='ray'>
          <visualize>1</visualize>
          <update_rate>10</update_rate>
          <ray>
            <scan>
              <horizontal>
                <samples>360</samples>
                <min_angle>-3.14</min_angle>
                <max_angle>3.14</max_angle>
                <resolution>1</resolution>
              </horizontal>
              <vertical>
                <samples>1</samples>
                <min_angle>0</min_angle>
                <max_angle>0</max_angle>
              </vertical>
            </scan>
            <range>
              <min>0.3</min>
              <max>12</max>
            </range>
          </ray>
          <plugin name='laser_controller' filename='libgazebo_ros_ray_sensor.so'>
            <ros>
              <argument>~/out:=scan</argument>
            </ros>
            <output_type>sensor_msgs/LaserScan</output_type>
            <frame_name>laser_frame</frame_name>
          </plugin>
          <pose>0 0 0.0848 0 -0 0</pose>
        </sensor>
        <self_collide>0</self_collide>
        <enable_wind>0</enable_wind>
        <kinematic>0</kinematic>
      </link>
      <joint name='rim_back_joint' type='revolute'>
        <pose relative_to='root_link'>-0.072 0 0 1.5708 -0 1.5708</pose>
        <parent>root_link</parent>
        <child>rim_back_link</child>
        <axis>
          <xyz>0 0 1</xyz>
          <limit>
            <effort>1</effort>
            <velocity>10</velocity>
            <lower>-1e+16</lower>
            <upper>1e+16</upper>
          </limit>
          <dynamics>
            <spring_reference>0</spring_reference>
            <spring_stiffness>0</spring_stiffness>
          </dynamics>
        </axis>
      </joint>
      <link name='rim_back_link'>
        <pose relative_to='rim_back_joint'>0 0 0 0 -0 0</pose>
        <inertial>
          <pose>0 0 0 0 -0 0</pose>
          <mass>0.05</mass>
          <inertia>
            <ixx>1.16667e-05</ixx>
            <ixy>0</ixy>
            <ixz>0</ixz>
            <iyy>1.16667e-05</iyy>
            <iyz>0</iyz>
            <izz>2.25e-05</izz>
          </inertia>
        </inertial>
        <collision name='rim_back_link_collision'>
          <pose>0 0 0 0 -0 0</pose>
          <geometry>
            <cylinder>
              <length>0.01</length>
              <radius>0.03</radius>
            </cylinder>
          </geometry>
          <max_contacts>10</max_contacts>
          <surface>
            <contact>
              <ode/>
            </contact>
            <bounce/>
            <friction>
              <torsional>
                <ode/>
              </torsional>
              <ode/>
            </friction>
          </surface>
        </collision>
        <visual name='rim_back_link_visual'>
          <pose>0 0 0 0 -0 0</pose>
          <geometry>
            <mesh>
              <scale>1 1 1</scale>
              <uri>file:///home/deepanshu/My_ROS/src/r_bot/description/meshes/wheels.dae</uri>
            </mesh>
          </geometry>
        </visual>
        <self_collide>0</self_collide>
        <enable_wind>0</enable_wind>
        <kinematic>0</kinematic>
      </link>
      <joint name='rim_left_joint' type='revolute'>
        <pose relative_to='root_link'>0.036 0.062354 -0.001 1.5708 0 -0.523599</pose>
        <parent>root_link</parent>
        <child>rim_left_link</child>
        <axis>
          <xyz>0 0 1</xyz>
          <limit>
            <effort>1</effort>
            <velocity>10</velocity>
            <lower>-1e+16</lower>
            <upper>1e+16</upper>
          </limit>
          <dynamics>
            <spring_reference>0</spring_reference>
            <spring_stiffness>0</spring_stiffness>
          </dynamics>
        </axis>
      </joint>
      <link name='rim_left_link'>
        <pose relative_to='rim_left_joint'>0 0 0 0 -0 0</pose>
        <inertial>
          <pose>0 0 0 0 -0 0</pose>
          <mass>0.05</mass>
          <inertia>
            <ixx>1.16667e-05</ixx>
            <ixy>0</ixy>
            <ixz>0</ixz>
            <iyy>1.16667e-05</iyy>
            <iyz>0</iyz>
            <izz>2.25e-05</izz>
          </inertia>
        </inertial>
        <collision name='rim_left_link_collision'>
          <pose>0 0 0 0 -0 0</pose>
          <geometry>
            <cylinder>
              <length>0.01</length>
              <radius>0.03</radius>
            </cylinder>
          </geometry>
          <max_contacts>10</max_contacts>
          <surface>
            <contact>
              <ode/>
            </contact>
            <bounce/>
            <friction>
              <torsional>
                <ode/>
              </torsional>
              <ode/>
            </friction>
          </surface>
        </collision>
        <visual name='rim_left_link_visual'>
          <pose>0 0 0 0 -0 0</pose>
          <geometry>
            <mesh>
              <scale>1 1 1</scale>
              <uri>file:///home/deepanshu/My_ROS/src/r_bot/description/meshes/wheels.dae</uri>
            </mesh>
          </geometry>
        </visual>
        <self_collide>0</self_collide>
        <enable_wind>0</enable_wind>
        <kinematic>0</kinematic>
      </link>
      <joint name='rim_right_joint' type='revolute'>
        <pose relative_to='root_link'>0.036 -0.062354 -0.001 1.5708 -0 0.523599</pose>
        <parent>root_link</parent>
        <child>rim_right_link</child>
        <axis>
          <xyz>0 0 1</xyz>
          <limit>
            <effort>1</effort>
            <velocity>10</velocity>
            <lower>-1e+16</lower>
            <upper>1e+16</upper>
          </limit>
          <dynamics>
            <spring_reference>0</spring_reference>
            <spring_stiffness>0</spring_stiffness>
          </dynamics>
        </axis>
      </joint>
      <link name='rim_right_link'>
        <pose relative_to='rim_right_joint'>0 0 0 0 -0 0</pose>
        <inertial>
          <pose>0 0 0 0 -0 0</pose>
          <mass>0.05</mass>
          <inertia>
            <ixx>1.16667e-05</ixx>
            <ixy>0</ixy>
            <ixz>0</ixz>
            <iyy>1.16667e-05</iyy>
            <iyz>0</iyz>
            <izz>2.25e-05</izz>
          </inertia>
        </inertial>
        <collision name='rim_right_link_collision'>
          <pose>0 0 0 0 -0 0</pose>
          <geometry>
            <cylinder>
              <length>0.01</length>
              <radius>0.03</radius>
            </cylinder>
          </geometry>
          <max_contacts>10</max_contacts>
          <surface>
            <contact>
              <ode/>
            </contact>
            <bounce/>
            <friction>
              <torsional>
                <ode/>
              </torsional>
              <ode/>
            </friction>
          </surface>
        </collision>
        <visual name='rim_right_link_visual'>
          <pose>0 0 0 0 -0 0</pose>
          <geometry>
            <mesh>
              <scale>1 1 1</scale>
              <uri>file:///home/deepanshu/My_ROS/src/r_bot/description/meshes/wheels.dae</uri>
            </mesh>
          </geometry>
        </visual>
        <self_collide>0</self_collide>
        <enable_wind>0</enable_wind>
        <kinematic>0</kinematic>
      </link>
      <static>0</static>
      <plugin name='gazebo_ros2_control' filename='libgazebo_ros2_control.so'>
        <parameters>/home/deepanshu/My_ROS/src/r_bot/config/Control.yaml</parameters>
      </plugin>
      <pose>0 0 0 0 -0 0</pose>
    </model>
    <model name='Construction Cone'>
      <link name='link'>
        <collision name='collision'>
          <geometry>
            <mesh>
              <scale>10 10 10</scale>
              <uri>model://construction_cone/meshes/construction_cone.dae</uri>
            </mesh>
          </geometry>
          <max_contacts>10</max_contacts>
          <surface>
            <contact>
              <ode/>
            </contact>
            <bounce/>
            <friction>
              <torsional>
                <ode/>
              </torsional>
              <ode/>
            </friction>
          </surface>
        </collision>
        <visual name='visual'>
          <geometry>
            <mesh>
              <scale>10 10 10</scale>
              <uri>model://construction_cone/meshes/construction_cone.dae</uri>
            </mesh>
          </geometry>
        </visual>
        <self_collide>0</self_collide>
        <inertial>
          <pose>0 0 0 0 -0 0</pose>
          <inertia>
            <ixx>1</ixx>
            <ixy>0</ixy>
            <ixz>0</ixz>
            <iyy>1</iyy>
            <iyz>0</iyz>
            <izz>1</izz>
          </inertia>
          <mass>1</mass>
        </inertial>
        <enable_wind>0</enable_wind>
        <kinematic>0</kinematic>
      </link>
      <pose>-0.126501 -0.750996 0 0 -0 0</pose>
    </model>
    <model name='Construction Cone_0'>
      <link name='link'>
        <collision name='collision'>
          <geometry>
            <mesh>
              <scale>10 10 10</scale>
              <uri>model://construction_cone/meshes/construction_cone.dae</uri>
            </mesh>
          </geometry>
          <max_contacts>10</max_contacts>
          <surface>
            <contact>
              <ode/>
            </contact>
            <bounce/>
            <friction>
              <torsional>
                <ode/>
              </torsional>
              <ode/>
            </friction>
          </surface>
        </collision>
        <visual name='visual'>
          <geometry>
            <mesh>
              <scale>10 10 10</scale>
              <uri>model://construction_cone/meshes/construction_cone.dae</uri>
            </mesh>
          </geometry>
        </visual>
        <self_collide>0</self_collide>
        <inertial>
          <pose>0 0 0 0 -0 0</pose>
          <inertia>
            <ixx>1</ixx>
            <ixy>0</ixy>
            <ixz>0</ixz>
            <iyy>1</iyy>
            <iyz>0</iyz>
            <izz>1</izz>
          </inertia>
          <mass>1</mass>
        </inertial>
        <enable_wind>0</enable_wind>
        <kinematic>0</kinematic>
      </link>
      <pose>-0.121901 -1.37907 0 0 -0 0</pose>
    </model>
    <state world_name='default'>
      <sim_time>40 614000000</sim_time>
      <real_time>40 939483949</real_time>
      <wall_time>1778184000 428094950</wall_time>
      <iterations>40614</iterations>
      <model name='Construction Cone'>
        <pose>-0.126501 -0.750996 -0 0 -0 0</pose>
        <scale>1 1 1</scale>
        <link name='link'>
          <pose>-0.126501 -0.750996 -0 0 -0 0</pose>
          <velocity>0 0 0 0 -0 0</velocity>
          <acceleration>0 -0 -0.008512 -2.58585 1.13682 3.14159</acceleration>
          <wrench>0 -0 -0.008512 0 -0 0</wrench>
        </link>
      </model>
      <model name='Construction Cone_0'>
        <pose>-0.121901 -1.37907 -0 0 -1e-06 0</pose>
        <scale>1 1 1</scale>
        <link name='link'>
          <pose>-0.121901 -1.37907 -0 0 -1e-06 0</pose>
          <velocity>0 0 0 0 -0 0</velocity>
          <acceleration>-0 0 0.008512 2.58585 -1.13682 -3.14159</acceleration>
          <wrench>-0 0 0.008512 0 -0 0</wrench>
        </link>
      </model>
      <model name='ground_plane'>
        <pose>0 0 0 0 -0 0</pose>
        <scale>1 1 1</scale>
        <link name='link'>
          <pose>0 0 0 0 -0 0</pose>
          <velocity>0 0 0 0 -0 0</velocity>
          <acceleration>0 0 0 0 -0 0</acceleration>
          <wrench>0 0 0 0 -0 0</wrench>
        </link>
      </model>
      <model name='my_bot'>
        <pose>-0.001104 -0.000105 0.030695 -2.7e-05 -0.009029 0.001163</pose>
        <scale>1 1 1</scale>
        <link name='rim_back_link'>
          <pose>-0.0731 -0.000189 0.030045 1.56155 -0.013143 1.57208</pose>
          <velocity>-2.2e-05 -0.000527 0 0.017865 7.2e-05 0.001739</velocity>
          <acceleration>0.004782 -1.01599 0.000251 0.210811 0.039019 -2.85054</acceleration>
          <wrench>0.000239 -0.050799 1.3e-05 0 -0 0</wrench>
        </link>
        <link name='rim_left_link'>
          <pose>0.03483 0.062289 0.030018 1.5754 0.359735 -0.520799</pose>
          <velocity>0.000181 -0.000178 -0.003397 0.013797 0.023076 -0.000338</velocity>
          <acceleration>0.210772 -0.673512 -6.75107 0.85832 -1.0325 2.40988</acceleration>
          <wrench>0.010539 -0.033676 -0.337553 0 -0 0</wrench>
        </link>
        <link name='rim_right_link'>
          <pose>0.034975 -0.062416 0.030022 1.56623 0.34669 0.523191</pose>
          <velocity>-0.000238 -0.000194 0.003416 0.005498 -0.007954 -0.000214</velocity>
          <acceleration>-0.213105 -0.689211 6.76821 3.00583 -0.508592 2.68191</acceleration>
          <wrench>-0.010655 -0.034461 0.33841 0 -0 0</wrench>
        </link>
        <link name='root_link'>
          <pose>-0.001104 -0.000105 0.030695 -2.7e-05 -0.009029 0.001163</pose>
          <velocity>-2.2e-05 -0.000459 -0 -0.05378 -5.3e-05 4.7e-05</velocity>
          <acceleration>0.001507 2.80388 -0.000797 -0.704955 -0.108002 0.521965</acceleration>
          <wrench>0.00038 0.706578 -0.000201 0 -0 0</wrench>
        </link>
      </model>
      <light name='sun'>
        <pose>0 0 10 0 -0 0</pose>
      </light>
    </state>
    <gui fullscreen='0'>
      <camera name='user_camera'>
        <pose>6.13302 -4.01778 20.262 -0 1.24764 2.64419</pose>
        <view_controller>orbit</view_controller>
        <projection_type>perspective</projection_type>
      </camera>
    </gui>
  </world>
</sdf>
